<?xml version="1.0"?>
<robot xmlns:xacro="http://www.ros.org/wiki/xacro">

    <!-- arm joints -->
    <joint name="right_shoulder_pitch_joint" type="revolute" >
        <parent link="body_link" />
        <child link="right_body_to_arm_link" />
        <origin xyz="0 -0.07 0.1" rpy="0 0 0" />
        <limit effort="1000" lower="${-3*PI/4}" upper="${3*PI/4}" velocity="1.0" />
        <axis xyz="0 1 0" />
    </joint>

    <joint name="right_shoulder_roll_joint" type="revolute" >
        <parent link="right_body_to_arm_link" />
        <child link="right_arm_link" />
        <origin xyz="0 -0.0215 0" rpy="0 0 0" />
        <limit effort="1000" lower="${-PI}" upper="0" velocity="1.0" />
        <axis xyz="1 0 0" />
    </joint>

    <joint name="right_arm_pitch_joint" type="revolute" >
        <parent link="right_arm_link" />
        <child link="right_hand_link" />
        <origin xyz="0 0 -0.084" rpy="0 ${PI/2} 0" />
        <limit effort="1000" lower="${-3*PI/4}" upper="${3*PI/4}" velocity="1.0" />
        <axis xyz="0 1 0" />
    </joint>

    <!-- arm link -->
    <link name="right_body_to_arm_link">
        <inertial>
            <mass value="0.5"/>
            <origin xyz="0 0 0"/>
            <inertia ixx="1.0" ixy="0.0" ixz="0.0" iyy="1.0" iyz="0.0" izz="1.0"/>
            </inertial>
        <visual>
            <origin xyz="0 0 0" rpy="0 0 ${PI}"/>
            <geometry>
                <mesh filename="package://opr_description/meshes/version1/STL/ARMS/body_to_arm.stl" />
            </geometry>
            <material name="grey" />
        </visual>
        <collision>
            <origin xyz="0 0 0" rpy="0 0 ${PI}"/>
            <geometry>
                <mesh filename="package://opr_description/meshes/version1/STL/ARMS/body_to_arm.stl" />
            </geometry>
        </collision>
    </link>

    <link name="right_arm_link">
        <inertial>
            <mass value="0.5"/>
            <origin xyz="0 0 0"/>
            <inertia ixx="1.0" ixy="0.0" ixz="0.0" iyy="1.0" iyz="0.0" izz="1.0"/>
            </inertial>
        <visual>
            <origin xyz="0 0 -0.042" rpy="0 0 ${PI}"/>
            <geometry>
                <mesh filename="package://opr_description/meshes/version1/STL/ARMS/right_arm.stl" />
            </geometry>
            <material name="blue" />
        </visual>
        <collision>
            <origin xyz="0 0 -0.042" rpy="0 0 ${PI}"/>
            <geometry>
                <mesh filename="package://opr_description/meshes/version1/STL/ARMS/right_arm.stl" />
            </geometry>
        </collision>
    </link>

    <link name="right_hand_link">
        <inertial>
            <mass value="0.5"/>
            <origin xyz="0 0 0"/>
            <inertia ixx="1.0" ixy="0.0" ixz="0.0" iyy="1.0" iyz="0.0" izz="1.0"/>
            </inertial>
        <visual>
            <origin xyz="0.09 0 0" rpy="${PI} 0 0"/>
            <geometry>
                <mesh filename="package://opr_description/meshes/version1/STL/ARMS/hand.stl" />
            </geometry>
            <material name="black" />
        </visual>
        <collision>
            <origin xyz="0.09 0 0" rpy="${PI} 0 0"/>
            <geometry>
                <mesh filename="package://opr_description/meshes/version1/STL/ARMS/hand.stl" />
            </geometry>
        </collision>
    </link>

</robot>
