<?xml version="1.0"?>
<robot xmlns:xacro="http://www.ros.org/wiki/xacro">

    <!-- arm joints -->
    <joint name="left_shoulder_pitch_joint" type="revolute" >
        <parent link="body_link" />
        <child link="left_shoulder_link" />
        <origin xyz="0.0 0.06 0.072" rpy="${-PI/2} 0 0" />
        <limit effort="1000" lower="${-3*PI/4}" upper="${3*PI/4}" velocity="1.0" />
        <axis xyz="0 0 1" />
    </joint>

    <joint name="left_shoulder_roll_joint" type="revolute" >
        <parent link="left_shoulder_link" />
        <child link="left_upper_arm_link" />
        <origin xyz="0 0 0.0315" rpy="0 ${PI/2} 0" />
        <limit effort="1000" lower="${-PI}" upper="${PI}" velocity="1.0" />
        <axis xyz="0 0 1" />
    </joint>

    <joint name="left_elbow_pitch_joint" type="revolute" >
        <parent link="left_upper_arm_link" />
        <child link="left_lower_arm_link" />
        <origin xyz="0 0.109 0" rpy="0 ${-PI/2} 0" />
        <limit effort="1000" lower="${-3*PI/4}" upper="${3*PI/4}" velocity="1.0" />
        <axis xyz="0 0 1" />
    </joint>

    <!-- arm link -->
    <link name="left_shoulder_link">
        <inertial>
            <mass value="0.09038"/>
            <origin xyz="0 0 0.0075"/>
            <inertia ixx="0.018183" ixy="0.0" ixz="0.0" iyy="0.027159" iyz="0.0" izz="0.014844"/>
        </inertial>
        <visual>
            <origin xyz="0 0 0" rpy="0 0 ${PI/2}"/>
            <geometry>
                <mesh filename="package://opr_description/meshes/version3/DAE/shoulder.dae" />
            </geometry>
        </visual>
        <collision>
            <!-- fix shoulder collision.stl -->
            <origin xyz="0 0 0" rpy="0 0 ${PI/2}"/>
            <geometry>
                <mesh filename="package://opr_description/meshes/version3/STL/shoulder.stl" />
            </geometry>
        </collision>
    </link>

    <link name="left_upper_arm_link">
        <inertial>
            <mass value="0.185658"/>
            <origin xyz="0 0.0545 0"/>
            <inertia ixx="0.380361" ixy="0.0" ixz="0.0" iyy="0.380345" iyz="-0.001759" izz="0.037424"/>
        </inertial>
        <visual>
            <origin xyz="0 0 0" rpy="0 ${PI/2} 0"/>
            <geometry>
                <mesh filename="package://opr_description/meshes/version3/DAE/arm.dae" />
            </geometry>
        </visual>
        <collision>
            <origin xyz="0 0 0" rpy="0 ${PI/2} 0"/>
            <geometry>
                <mesh filename="package://opr_description/meshes/version3/STL/arm.stl" />
            </geometry>
        </collision>
    </link>

    <link name="left_lower_arm_link">
        <inertial>
            <mass value="0.059757"/>
            <origin xyz="0 0.132001 0"/>
            <inertia ixx="0.014579" ixy="-0.022117" ixz="0.0" iyy="0.228745" iyz="-0.001759" izz="0.237824"/>
        </inertial>
        <visual>
            <origin xyz="0 0 0" rpy="0 0 ${PI/2}"/>
            <geometry>
                <mesh filename="package://opr_description/meshes/version3/DAE/hand.dae" />
            </geometry>
        </visual>
        <collision>
            <origin xyz="0 0 0" rpy="0 0 ${PI/2}"/>
            <geometry>
                <mesh filename="package://opr_description/meshes/version3/STL/hand.stl" />
            </geometry>
        </collision>
    </link>

</robot>
